Traceback (most recent call last):
  File "pyautogui\__init__.py", line 172, in wrapper
  File "pyautogui\__init__.py", line 210, in locateOnScreen
  File "pyscreeze\__init__.py", line 405, in locateOnScreen
  File "pyscreeze\__init__.py", line 383, in locate
  File "pyscreeze\__init__.py", line 257, in _locateAll_opencv
pyscreeze.ImageNotFoundException: Could not locate the image (highest confidence = 0.346)

During handling of the above exception, another exception occurred:

Traceback (most recent call last):
  File "bot3010gpt3.py", line 132, in <module>
  File "bot3010gpt3.py", line 62, in run_script
  File "pyautogui\__init__.py", line 174, in wrapper
pyautogui.ImageNotFoundException
